Workbook

Sheet Resumo
A1: Resumo do Cálculo
A2: Nome do Segurado: | B2: SEGURADO EXEMPLO | D2: NIT: | E2: 000.00000.00-0
A3: CPF: | B3: 000.000.000-00 | D3: Data de Nascimento: | E3: 13/08/1976
A4: Sexo: | B4: Masculino | D4: Nº do Benefício: | E4: 000.000.000-0
A5: Espécie do Benefício: | B5: 46 - Aposentadoria Especial | D5: Nº do Processo: | E5: 0000000-00.2021.4.01.3800
A6: Início do Benefício (DIB): | B6: 16/10/2019 | D6: Data da Atualização: | E6: 08/05/2025
A7: Ajuizamento: | B7: 21/01/2021 | D7: Data da Prescrição: | E7: 16/10/2019
A9: Renda Mensal Corrigida até 08/05/2025: | B9: ='Diferenças'!B93
A10: Principal: | B10: ='Diferenças'!D91
A11: Correção Monetária: | B11: ='Diferenças'!M91-'Diferenças'!D91
A12: Total Atualizado: | B12: ='Diferenças'!M91
A13: Valor dos Juros: | B13: ='Diferenças'!N91
A14: (-) Acordo/Deságio: | B14: ='Parâmetros'!$B$24
A15: Total Atualizado + Valor dos Juros - Valor Acordo: | B15: =B12+B13-B14
A16: Honorários Sobre a Base de Cálculo Atualizada: | B16: ='Honorários'!$B$90
A17: Honorários Sobre os Juros da Base de Cálculo: | B17: ='Honorários'!$B$91
A18: Valor Fixo de Honorários: | B18: ='Honorários'!$B$92
A19: Total Atualizado de Honorários: | B19: ='Honorários'!$B$93
A20: Multa: | B20: ='Parâmetros'!$B$25
A21: Dano Moral/Material: | B21: ='Parâmetros'!$B$26
A22: Total Geral: | B22: =B15+B19+B20+B21
A23: Total geral atualizado até 08/05/2025
A24: O valor equivale a (salários mínimos): | B24: =ROUND(B22/'Parâmetros'!$B$27,2)
A26: Valor da causa (art. 292, §§ 1º e 2º, do CPC)
A27: Parcelas vencidas (atualizadas + juros): | B27: =B15
A28: 12 parcelas vincendas (12 × R.M.A.): | B28: =ROUND(12*'Diferenças'!B93,2)
A29: Valor da causa: | B29: =B27+B28
A30: Limite do JEF (60 salários mínimos): | B30: =ROUND(60*'Parâmetros'!$B$27,2)
A31: Competência: | B31: =IF(B29<=B30,"Juizado Especial Federal","Vara Federal (ou renúncia ao excedente)")
A34: Cristiano da Silva Ottone OAB/MG 152.214

Sheet Parâmetros
A1: Parâmetros do cálculo (células amarelas podem ser editadas)
A3: Nome do segurado | B3: SEGURADO EXEMPLO
A4: NIT | B4: 000.00000.00-0
A5: CPF | B5: 000.000.000-00
A6: Data de nascimento | B6: 13/08/1976
A7: Sexo | B7: M
A8: Nº do benefício | B8: 000.000.000-0
A9: Espécie | B9: 46 - Aposentadoria Especial
A10: DER
A11: DIB | B11: 16/10/2019
A12: RMI (renda mensal inicial) | B12: 4119.82
A13: Nº do processo | B13: 0000000-00.2021.4.01.3800
A14: Inscrição no INSS | B14: 02/01/1992
A15: Ajuizamento | B15: 21/01/2021
A16: Citação (início dos juros de mora) | B16: 01/10/2021
A17: Data da prescrição quinquenal | B17: 16/10/2019
A18: Data da atualização | B18: 08/05/2025
A19: Diferenças desde | B19: 16/10/2019
A20: Diferenças até | B20: 28/02/2025
A21: Honorários (%) | B21: 10
A22: Honorários: parcelas até (Súmula 111/STJ) | B22: todas
A23: Honorários: valor fixo | B23: 0
A24: (-) Acordo/Deságio | B24: 0
A25: Multa | B25: 0
A26: Dano moral/material | B26: 0
A27: Salário mínimo na data da atualização | B27: 1518
A28: Índice de correção | B28: INPC
A29: Responsável pelo cálculo | B29: Cristiano da Silva Ottone
A30: OAB | B30: OAB/MG 152.214

Sheet Evolução RMI
A1: Relatório da Evolução da R.M.I.
A2: Nome do Segurado: | B2: SEGURADO EXEMPLO | D2: NIT: | E2: 000.00000.00-0
A3: CPF: | B3: 000.000.000-00 | D3: Data de Nascimento: | E3: 13/08/1976
A4: Sexo: | B4: Masculino | D4: Nº do Benefício: | E4: 000.000.000-0
A5: Espécie do Benefício: | B5: 46 - Aposentadoria Especial | D5: Nº do Processo: | E5: 0000000-00.2021.4.01.3800
A6: Início do Benefício (DIB): | B6: 16/10/2019 | D6: Data da Atualização: | E6: 08/05/2025
A7: Ajuizamento: | B7: 21/01/2021 | D7: Data da Prescrição: | E7: 16/10/2019
A9: Data | B9: Valor do Benefício | C9: Reajuste (%) | D9: Teto do Benefício | E9: Salário Mínimo | F9: Benefício Mensal | G9: Fração (pró-rata) | H9: Benefício Considerado
A10: 10/2019 | B10: ='Parâmetros'!$B$12 | D10: 5839.45 | E10: 998 | F10: =MAX(E10,MIN(D10,IF(C10="",B10,TRUNC(B10*(1+C10/100),2)))) | G10: 0.5 | H10: =TRUNC(F10*G10,2)
A11: 11/2019 | B11: =F10 | D11: 5839.45 | E11: 998 | F11: =MAX(E11,MIN(D11,IF(C11="",B11,TRUNC(B11*(1+C11/100),2)))) | G11: 1 | H11: =TRUNC(F11*G11,2)
A12: 12/2019 | B12: =F11 | D12: 5839.45 | E12: 998 | F12: =MAX(E12,MIN(D12,IF(C12="",B12,TRUNC(B12*(1+C12/100),2)))) | G12: 1 | H12: =TRUNC(F12*G12,2)
A13: 01/2020 | B13: =F12 | C13: 1.81 | D13: 6101.06 | E13: 1039 | F13: =MAX(E13,MIN(D13,IF(C13="",B13,TRUNC(B13*(1+C13/100),2)))) | G13: 1 | H13: =TRUNC(F13*G13,2)
A14: 02/2020 | B14: =F13 | D14: 6101.06 | E14: 1045 | F14: =MAX(E14,MIN(D14,IF(C14="",B14,TRUNC(B14*(1+C14/100),2)))) | G14: 1 | H14: =TRUNC(F14*G14,2)
A15: 03/2020 | B15: =F14 | D15: 6101.06 | E15: 1045 | F15: =MAX(E15,MIN(D15,IF(C15="",B15,TRUNC(B15*(1+C15/100),2)))) | G15: 1 | H15: =TRUNC(F15*G15,2)
A16: 04/2020 | B16: =F15 | D16: 6101.06 | E16: 1045 | F16: =MAX(E16,MIN(D16,IF(C16="",B16,TRUNC(B16*(1+C16/100),2)))) | G16: 1 | H16: =TRUNC(F16*G16,2)
A17: 05/2020 | B17: =F16 | D17: 6101.06 | E17: 1045 | F17: =MAX(E17,MIN(D17,IF(C17="",B17,TRUNC(B17*(1+C17/100),2)))) | G17: 1 | H17: =TRUNC(F17*G17,2)
A18: 06/2020 | B18: =F17 | D18: 6101.06 | E18: 1045 | F18: =MAX(E18,MIN(D18,IF(C18="",B18,TRUNC(B18*(1+C18/100),2)))) | G18: 1 | H18: =TRUNC(F18*G18,2)
A19: 07/2020 | B19: =F18 | D19: 6101.06 | E19: 1045 | F19: =MAX(E19,MIN(D19,IF(C19="",B19,TRUNC(B19*(1+C19/100),2)))) | G19: 1 | H19: =TRUNC(F19*G19,2)
A20: 08/2020 | B20: =F19 | D20: 6101.06 | E20: 1045 | F20: =MAX(E20,MIN(D20,IF(C20="",B20,TRUNC(B20*(1+C20/100),2)))) | G20: 1 | H20: =TRUNC(F20*G20,2)
A21: 09/2020 | B21: =F20 | D21: 6101.06 | E21: 1045 | F21: =MAX(E21,MIN(D21,IF(C21="",B21,TRUNC(B21*(1+C21/100),2)))) | G21: 1 | H21: =TRUNC(F21*G21,2)
A22: 10/2020 | B22: =F21 | D22: 6101.06 | E22: 1045 | F22: =MAX(E22,MIN(D22,IF(C22="",B22,TRUNC(B22*(1+C22/100),2)))) | G22: 1 | H22: =TRUNC(F22*G22,2)
A23: 11/2020 | B23: =F22 | D23: 6101.06 | E23: 1045 | F23: =MAX(E23,MIN(D23,IF(C23="",B23,TRUNC(B23*(1+C23/100),2)))) | G23: 1 | H23: =TRUNC(F23*G23,2)
A24: 12/2020 | B24: =F23 | D24: 6101.06 | E24: 1045 | F24: =MAX(E24,MIN(D24,IF(C24="",B24,TRUNC(B24*(1+C24/100),2)))) | G24: 1 | H24: =TRUNC(F24*G24,2)
A25: 01/2021 | B25: =F24 | C25: 5.45 | D25: 6433.57 | E25: 1100 | F25: =MAX(E25,MIN(D25,IF(C25="",B25,TRUNC(B25*(1+C25/100),2)))) | G25: 1 | H25: =TRUNC(F25*G25,2)
A26: 02/2021 | B26: =F25 | D26: 6433.57 | E26: 1100 | F26: =MAX(E26,MIN(D26,IF(C26="",B26,TRUNC(B26*(1+C26/100),2)))) | G26: 1 | H26: =TRUNC(F26*G26,2)
A27: 03/2021 | B27: =F26 | D27: 6433.57 | E27: 1100 | F27: =MAX(E27,MIN(D27,IF(C27="",B27,TRUNC(B27*(1+C27/100),2)))) | G27: 1 | H27: =TRUNC(F27*G27,2)
A28: 04/2021 | B28: =F27 | D28: 6433.57 | E28: 1100 | F28: =MAX(E28,MIN(D28,IF(C28="",B28,TRUNC(B28*(1+C28/100),2)))) | G28: 1 | H28: =TRUNC(F28*G28,2)
A29: 05/2021 | B29: =F28 | D29: 6433.57 | E29: 1100 | F29: =MAX(E29,MIN(D29,IF(C29="",B29,TRUNC(B29*(1+C29/100),2)))) | G29: 1 | H29: =TRUNC(F29*G29,2)
A30: 06/2021 | B30: =F29 | D30: 6433.57 | E30: 1100 | F30: =MAX(E30,MIN(D30,IF(C30="",B30,TRUNC(B30*(1+C30/100),2)))) | G30: 1 | H30: =TRUNC(F30*G30,2)
A31: 07/2021 | B31: =F30 | D31: 6433.57 | E31: 1100 | F31: =MAX(E31,MIN(D31,IF(C31="",B31,TRUNC(B31*(1+C31/100),2)))) | G31: 1 | H31: =TRUNC(F31*G31,2)
A32: 08/2021 | B32: =F31 | D32: 6433.57 | E32: 1100 | F32: =MAX(E32,MIN(D32,IF(C32="",B32,TRUNC(B32*(1+C32/100),2)))) | G32: 1 | H32: =TRUNC(F32*G32,2)
A33: 09/2021 | B33: =F32 | D33: 6433.57 | E33: 1100 | F33: =MAX(E33,MIN(D33,IF(C33="",B33,TRUNC(B33*(1+C33/100),2)))) | G33: 1 | H33: =TRUNC(F33*G33,2)
A34: 10/2021 | B34: =F33 | D34: 6433.57 | E34: 1100 | F34: =MAX(E34,MIN(D34,IF(C34="",B34,TRUNC(B34*(1+C34/100),2)))) | G34: 1 | H34: =TRUNC(F34*G34,2)
A35: 11/2021 | B35: =F34 | D35: 6433.57 | E35: 1100 | F35: =MAX(E35,MIN(D35,IF(C35="",B35,TRUNC(B35*(1+C35/100),2)))) | G35: 1 | H35: =TRUNC(F35*G35,2)
A36: 12/2021 | B36: =F35 | D36: 6433.57 | E36: 1100 | F36: =MAX(E36,MIN(D36,IF(C36="",B36,TRUNC(B36*(1+C36/100),2)))) | G36: 1 | H36: =TRUNC(F36*G36,2)
A37: 01/2022 | B37: =F36 | C37: 10.16 | D37: 7087.22 | E37: 1212 | F37: =MAX(E37,MIN(D37,IF(C37="",B37,TRUNC(B37*(1+C37/100),2)))) | G37: 1 | H37: =TRUNC(F37*G37,2)
A38: 02/2022 | B38: =F37 | D38: 7087.22 | E38: 1212 | F38: =MAX(E38,MIN(D38,IF(C38="",B38,TRUNC(B38*(1+C38/100),2)))) | G38: 1 | H38: =TRUNC(F38*G38,2)
A39: 03/2022 | B39: =F38 | D39: 7087.22 | E39: 1212 | F39: =MAX(E39,MIN(D39,IF(C39="",B39,TRUNC(B39*(1+C39/100),2)))) | G39: 1 | H39: =TRUNC(F39*G39,2)
A40: 04/2022 | B40: =F39 | D40: 7087.22 | E40: 1212 | F40: =MAX(E40,MIN(D40,IF(C40="",B40,TRUNC(B40*(1+C40/100),2)))) | G40: 1 | H40: =TRUNC(F40*G40,2)
A41: 05/2022 | B41: =F40 | D41: 7087.22 | E41: 1212 | F41: =MAX(E41,MIN(D41,IF(C41="",B41,TRUNC(B41*(1+C41/100),2)))) | G41: 1 | H41: =TRUNC(F41*G41,2)
...

Sheet Diferenças
A1: Relatório das Diferenças Não Recebidas
A2: Nome do Segurado: | B2: SEGURADO EXEMPLO | D2: NIT: | E2: 000.00000.00-0
A3: CPF: | B3: 000.000.000-00 | D3: Data de Nascimento: | E3: 13/08/1976
A4: Sexo: | B4: Masculino | D4: Nº do Benefício: | E4: 000.000.000-0
A5: Espécie do Benefício: | B5: 46 - Aposentadoria Especial | D5: Nº do Processo: | E5: 0000000-00.2021.4.01.3800
A6: Início do Benefício (DIB): | B6: 16/10/2019 | D6: Data da Atualização: | E6: 08/05/2025
A7: Ajuizamento: | B7: 21/01/2021 | D7: Data da Prescrição: | E7: 16/10/2019
A9: Correção monetária: Tabela da Justiça Federal (INPC; IGP-DI de 05/1996 a 08/2006), pró-rata no 1º mês, até 11/2021.
A10: Juros de mora a partir da citação: 1% a.m. até 06/2009; 0,5% a.m. até 04/2012; juros da poupança (Lei 12.703/2012) até 11/2021 — sem capitalização.
A11: De 12/2021 a 08/2025: SELIC acumulada (simples), uma única vez, substituindo correção e juros (EC 113/2021, art. 3º; Tema 1.419/STF).
A12: Diferenças consideradas de 16/10/2019 a 28/02/2025.
A14: Data | B14: Valor do Benefício | C14: Valor Já Recebido | D14: Diferença | E14: Índice de Atualização | F14: Valor Atualizado | G14: % Juros | H14: Valor dos Juros | I14: Valor Atualizado + Juros | J14: % Selic | K14: Valor da Selic | L14: Total Atualizado | M14: Base atualizada | N14: Juros (todos) | O14: Ano | P14: Tipo
A15: 10/2019 | B15: ='Evolução RMI'!H10 | C15: 0 | D15: =B15-C15 | E15: 1.1738057 | F15: =ROUND(D15*E15,2) | G15: 0.7987 | H15: =ROUND(F15*G15/100,2) | I15: =F15+H15 | J15: 39.21 | K15: =ROUND(I15*J15/100,2) | L15: =I15+K15 | M15: =F15 | N15: =H15+K15 | O15: 2019 | P15: mensal
A16: 11/2019 | B16: ='Evolução RMI'!H11 | C16: 0 | D16: =B16-C16 | E16: 1.1735635 | F16: =ROUND(D16*E16,2) | G16: 0.7987 | H16: =ROUND(F16*G16/100,2) | I16: =F16+H16 | J16: 39.21 | K16: =ROUND(I16*J16/100,2) | L16: =I16+K16 | M16: =F16 | N16: =H16+K16 | O16: 2019 | P16: mensal
A17: 12/2019 | B17: ='Evolução RMI'!H12 | C17: 0 | D17: =B17-C17 | E17: 1.1672602 | F17: =ROUND(D17*E17,2) | G17: 0.7987 | H17: =ROUND(F17*G17/100,2) | I17: =F17+H17 | J17: 39.21 | K17: =ROUND(I17*J17/100,2) | L17: =I17+K17 | M17: =F17 | N17: =H17+K17 | O17: 2019 | P17: mensal
A18: 13º | B18: =TRUNC('Evolução RMI'!F12*3/12,2) | C18: 0 | D18: =B18-C18 | E18: 1.1672602 | F18: =ROUND(D18*E18,2) | G18: 0.7987 | H18: =ROUND(F18*G18/100,2) | I18: =F18+H18 | J18: 39.21 | K18: =ROUND(I18*J18/100,2) | L18: =I18+K18 | M18: =F18 | N18: =H18+K18 | O18: 2019 | P18: 13º
A19: 01/2020 | B19: ='Evolução RMI'!H13 | C19: 0 | D19: =B19-C19 | E19: 1.1531913 | F19: =ROUND(D19*E19,2) | G19: 0.7987 | H19: =ROUND(F19*G19/100,2) | I19: =F19+H19 | J19: 39.21 | K19: =ROUND(I19*J19/100,2) | L19: =I19+K19 | M19: =F19 | N19: =H19+K19 | O19: 2020 | P19: mensal
A20: 02/2020 | B20: ='Evolução RMI'!H14 | C20: 0 | D20: =B20-C20 | E20: 1.1510044 | F20: =ROUND(D20*E20,2) | G20: 0.7987 | H20: =ROUND(F20*G20/100,2) | I20: =F20+H20 | J20: 39.21 | K20: =ROUND(I20*J20/100,2) | L20: =I20+K20 | M20: =F20 | N20: =H20+K20 | O20: 2020 | P20: mensal
A21: 03/2020 | B21: ='Evolução RMI'!H15 | C21: 0 | D21: =B21-C21 | E21: 1.149051 | F21: =ROUND(D21*E21,2) | G21: 0.7987 | H21: =ROUND(F21*G21/100,2) | I21: =F21+H21 | J21: 39.21 | K21: =ROUND(I21*J21/100,2) | L21: =I21+K21 | M21: =F21 | N21: =H21+K21 | O21: 2020 | P21: mensal
A22: 04/2020 | B22: ='Evolução RMI'!H16 | C22: 0 | D22: =B22-C22 | E22: 1.1469864 | F22: =ROUND(D22*E22,2) | G22: 0.7987 | H22: =ROUND(F22*G22/100,2) | I22: =F22+H22 | J22: 39.21 | K22: =ROUND(I22*J22/100,2) | L22: =I22+K22 | M22: =F22 | N22: =H22+K22 | O22: 2020 | P22: mensal
A23: 13º | B23: =TRUNC('Evolução RMI'!F16/2,2) | C23: 0 | D23: =B23-C23 | E23: 1.1469864 | F23: =ROUND(D23*E23,2) | G23: 0.7987 | H23: =ROUND(F23*G23/100,2) | I23: =F23+H23 | J23: 39.21 | K23: =ROUND(I23*J23/100,2) | L23: =I23+K23 | M23: =F23 | N23: =H23+K23 | O23: 2020 | P23: 13º
A24: 05/2020 | B24: ='Evolução RMI'!H17 | C24: 0 | D24: =B24-C24 | E24: 1.1496306 | F24: =ROUND(D24*E24,2) | G24: 0.7987 | H24: =ROUND(F24*G24/100,2) | I24: =F24+H24 | J24: 39.21 | K24: =ROUND(I24*J24/100,2) | L24: =I24+K24 | M24: =F24 | N24: =H24+K24 | O24: 2020 | P24: mensal
A25: 13º | B25: =TRUNC('Evolução RMI'!F17*12/12-'Evolução RMI'!F16/2,2) | C25: 0 | D25: =B25-C25 | E25: 1.1496306 | F25: =ROUND(D25*E25,2) | G25: 0.7987 | H25: =ROUND(F25*G25/100,2) | I25: =F25+H25 | J25: 39.21 | K25: =ROUND(I25*J25/100,2) | L25: =I25+K25 | M25: =F25 | N25: =H25+K25 | O25: 2020 | P25: 13º
A26: 06/2020 | B26: ='Evolução RMI'!H18 | C26: 0 | D26: =B26-C26 | E26: 1.1525119 | F26: =ROUND(D26*E26,2) | G26: 0.7987 | H26: =ROUND(F26*G26/100,2) | I26: =F26+H26 | J26: 39.21 | K26: =ROUND(I26*J26/100,2) | L26: =I26+K26 | M26: =F26 | N26: =H26+K26 | O26: 2020 | P26: mensal
A27: 07/2020 | B27: ='Evolução RMI'!H19 | C27: 0 | D27: =B27-C27 | E27: 1.1490647 | F27: =ROUND(D27*E27,2) | G27: 0.7987 | H27: =ROUND(F27*G27/100,2) | I27: =F27+H27 | J27: 39.21 | K27: =ROUND(I27*J27/100,2) | L27: =I27+K27 | M27: =F27 | N27: =H27+K27 | O27: 2020 | P27: mensal
A28: 08/2020 | B28: ='Evolução RMI'!H20 | C28: 0 | D28: =B28-C28 | E28: 1.1440309 | F28: =ROUND(D28*E28,2) | G28: 0.7987 | H28: =ROUND(F28*G28/100,2) | I28: =F28+H28 | J28: 39.21 | K28: =ROUND(I28*J28/100,2) | L28: =I28+K28 | M28: =F28 | N28: =H28+K28 | O28: 2020 | P28: mensal
A29: 09/2020 | B29: ='Evolução RMI'!H21 | C29: 0 | D29: =B29-C29 | E29: 1.1399272 | F29: =ROUND(D29*E29,2) | G29: 0.7987 | H29: =ROUND(F29*G29/100,2) | I29: =F29+H29 | J29: 39.21 | K29: =ROUND(I29*J29/100,2) | L29: =I29+K29 | M29: =F29 | N29: =H29+K29 | O29: 2020 | P29: mensal
A30: 10/2020 | B30: ='Evolução RMI'!H22 | C30: 0 | D30: =B30-C30 | E30: 1.1300954 | F30: =ROUND(D30*E30,2) | G30: 0.7987 | H30: =ROUND(F30*G30/100,2) | I30: =F30+H30 | J30: 39.21 | K30: =ROUND(I30*J30/100,2) | L30: =I30+K30 | M30: =F30 | N30: =H30+K30 | O30: 2020 | P30: mensal
A31: 11/2020 | B31: ='Evolução RMI'!H23 | C31: 0 | D31: =B31-C31 | E31: 1.1201263 | F31: =ROUND(D31*E31,2) | G31: 0.7987 | H31: =ROUND(F31*G31/100,2) | I31: =F31+H31 | J31: 39.21 | K31: =ROUND(I31*J31/100,2) | L31: =I31+K31 | M31: =F31 | N31: =H31+K31 | O31: 2020 | P31: mensal
A32: 12/2020 | B32: ='Evolução RMI'!H24 | C32: 0 | D32: =B32-C32 | E32: 1.1095852 | F32: =ROUND(D32*E32,2) | G32: 0.7987 | H32: =ROUND(F32*G32/100,2) | I32: =F32+H32 | J32: 39.21 | K32: =ROUND(I32*J32/100,2) | L32: =I32+K32 | M32: =F32 | N32: =H32+K32 | O32: 2020 | P32: mensal
A33: 01/2021 | B33: ='Evolução RMI'!H25 | C33: 0 | D33: =B33-C33 | E33: 1.0936184 | F33: =ROUND(D33*E33,2) | G33: 0.7987 | H33: =ROUND(F33*G33/100,2) | I33: =F33+H33 | J33: 39.21 | K33: =ROUND(I33*J33/100,2) | L33: =I33+K33 | M33: =F33 | N33: =H33+K33 | O33: 2021 | P33: mensal
A34: 02/2021 | B34: ='Evolução RMI'!H26 | C34: 0 | D34: =B34-C34 | E34: 1.0906735 | F34: =ROUND(D34*E34,2) | G34: 0.7987 | H34: =ROUND(F34*G34/100,2) | I34: =F34+H34 | J34: 39.21 | K34: =ROUND(I34*J34/100,2) | L34: =I34+K34 | M34: =F34 | N34: =H34+K34 | O34: 2021 | P34: mensal
A35: 03/2021 | B35: ='Evolução RMI'!H27 | C35: 0 | D35: =B35-C35 | E35: 1.0818028 | F35: =ROUND(D35*E35,2) | G35: 0.7987 | H35: =ROUND(F35*G35/100,2) | I35: =F35+H35 | J35: 39.21 | K35: =ROUND(I35*J35/100,2) | L35: =I35+K35 | M35: =F35 | N35: =H35+K35 | O35: 2021 | P35: mensal
A36: 04/2021 | B36: ='Evolução RMI'!H28 | C36: 0 | D36: =B36-C36 | E36: 1.0725786 | F36: =ROUND(D36*E36,2) | G36: 0.7987 | H36: =ROUND(F36*G36/100,2) | I36: =F36+H36 | J36: 39.21 | K36: =ROUND(I36*J36/100,2) | L36: =I36+K36 | M36: =F36 | N36: =H36+K36 | O36: 2021 | P36: mensal
A37: 05/2021 | B37: ='Evolução RMI'!H29 | C37: 0 | D37: =B37-C37 | E37: 1.0685182 | F37: =ROUND(D37*E37,2) | G37: 0.7987 | H37: =ROUND(F37*G37/100,2) | I37: =F37+H37 | J37: 39.21 | K37: =ROUND(I37*J37/100,2) | L37: =I37+K37 | M37: =F37 | N37: =H37+K37 | O37: 2021 | P37: mensal
A38: 13º | B38: =TRUNC('Evolução RMI'!F29/2,2) | C38: 0 | D38: =B38-C38 | E38: 1.0685182 | F38: =ROUND(D38*E38,2) | G38: 0.7987 | H38: =ROUND(F38*G38/100,2) | I38: =F38+H38 | J38: 39.21 | K38: =ROUND(I38*J38/100,2) | L38: =I38+K38 | M38: =F38 | N38: =H38+K38 | O38: 2021 | P38: 13º
A39: 06/2021 | B39: ='Evolução RMI'!H30 | C39: 0 | D39: =B39-C39 | E39: 1.058358 | F39: =ROUND(D39*E39,2) | G39: 0.7987 | H39: =ROUND(F39*G39/100,2) | I39: =F39+H39 | J39: 39.21 | K39: =ROUND(I39*J39/100,2) | L39: =I39+K39 | M39: =F39 | N39: =H39+K39 | O39: 2021 | P39: mensal
A40: 13º | B40: =TRUNC('Evolução RMI'!F30*12/12-'Evolução RMI'!F29/2,2) | C40: 0 | D40: =B40-C40 | E40: 1.058358 | F40: =ROUND(D40*E40,2) | G40: 0.7987 | H40: =ROUND(F40*G40/100,2) | I40: =F40+H40 | J40: 39.21 | K40: =ROUND(I40*J40/100,2) | L40: =I40+K40 | M40: =F40 | N40: =H40+K40 | O40: 2021 | P40: 13º
A41: 07/2021 | B41: ='Evolução RMI'!H31 | C41: 0 | D41: =B41-C41 | E41: 1.0520457 | F41: =ROUND(D41*E41,2) | G41: 0.7987 | H41: =ROUND(F41*G41/100,2) | I41: =F41+H41 | J41: 39.21 | K41: =ROUND(I41*J41/100,2) | L41: =I41+K41 | M41: =F41 | N41: =H41+K41 | O41: 2021 | P41: mensal
A42: 08/2021 | B42: ='Evolução RMI'!H32 | C42: 0 | D42: =B42-C42 | E42: 1.0414232 | F42: =ROUND(D42*E42,2) | G42: 0.7987 | H42: =ROUND(F42*G42/100,2) | I42: =F42+H42 | J42: 39.21 | K42: =ROUND(I42*J42/100,2) | L42: =I42+K42 | M42: =F42 | N42: =H42+K42 | O42: 2021 | P42: mensal
...

Sheet Honorários
A1: Cálculo dos Honorários
A2: Nome do Segurado: | B2: SEGURADO EXEMPLO | D2: NIT: | E2: 000.00000.00-0
A3: CPF: | B3: 000.000.000-00 | D3: Data de Nascimento: | E3: 13/08/1976
A4: Sexo: | B4: Masculino | D4: Nº do Benefício: | E4: 000.000.000-0
A5: Espécie do Benefício: | B5: 46 - Aposentadoria Especial | D5: Nº do Processo: | E5: 0000000-00.2021.4.01.3800
A6: Início do Benefício (DIB): | B6: 16/10/2019 | D6: Data da Atualização: | E6: 08/05/2025
A7: Ajuizamento: | B7: 21/01/2021 | D7: Data da Prescrição: | E7: 16/10/2019
A9: Honorários de | B9: ='Parâmetros'!$B$21 | C9: % sobre a base de cálculo atualizada e sobre os juros.
A11: Data | B11: Base de Cálculo | C11: Base de Cálculo Atualizada | D11: Juros Sobre a Base de Cálculo | E11: Base Atualizada + Juros | F11: Valor Calculado
A12: 10/2019 | B12: ='Diferenças'!D15 | C12: ='Diferenças'!M15 | D12: ='Diferenças'!N15 | E12: =C12+D12 | F12: =ROUND(E12*'Parâmetros'!$B$21/100,2)
A13: 11/2019 | B13: ='Diferenças'!D16 | C13: ='Diferenças'!M16 | D13: ='Diferenças'!N16 | E13: =C13+D13 | F13: =ROUND(E13*'Parâmetros'!$B$21/100,2)
A14: 12/2019 | B14: ='Diferenças'!D17 | C14: ='Diferenças'!M17 | D14: ='Diferenças'!N17 | E14: =C14+D14 | F14: =ROUND(E14*'Parâmetros'!$B$21/100,2)
A15: 13º | B15: ='Diferenças'!D18 | C15: ='Diferenças'!M18 | D15: ='Diferenças'!N18 | E15: =C15+D15 | F15: =ROUND(E15*'Parâmetros'!$B$21/100,2)
A16: 01/2020 | B16: ='Diferenças'!D19 | C16: ='Diferenças'!M19 | D16: ='Diferenças'!N19 | E16: =C16+D16 | F16: =ROUND(E16*'Parâmetros'!$B$21/100,2)
A17: 02/2020 | B17: ='Diferenças'!D20 | C17: ='Diferenças'!M20 | D17: ='Diferenças'!N20 | E17: =C17+D17 | F17: =ROUND(E17*'Parâmetros'!$B$21/100,2)
A18: 03/2020 | B18: ='Diferenças'!D21 | C18: ='Diferenças'!M21 | D18: ='Diferenças'!N21 | E18: =C18+D18 | F18: =ROUND(E18*'Parâmetros'!$B$21/100,2)
A19: 04/2020 | B19: ='Diferenças'!D22 | C19: ='Diferenças'!M22 | D19: ='Diferenças'!N22 | E19: =C19+D19 | F19: =ROUND(E19*'Parâmetros'!$B$21/100,2)
A20: 13º | B20: ='Diferenças'!D23 | C20: ='Diferenças'!M23 | D20: ='Diferenças'!N23 | E20: =C20+D20 | F20: =ROUND(E20*'Parâmetros'!$B$21/100,2)
A21: 05/2020 | B21: ='Diferenças'!D24 | C21: ='Diferenças'!M24 | D21: ='Diferenças'!N24 | E21: =C21+D21 | F21: =ROUND(E21*'Parâmetros'!$B$21/100,2)
A22: 13º | B22: ='Diferenças'!D25 | C22: ='Diferenças'!M25 | D22: ='Diferenças'!N25 | E22: =C22+D22 | F22: =ROUND(E22*'Parâmetros'!$B$21/100,2)
A23: 06/2020 | B23: ='Diferenças'!D26 | C23: ='Diferenças'!M26 | D23: ='Diferenças'!N26 | E23: =C23+D23 | F23: =ROUND(E23*'Parâmetros'!$B$21/100,2)
... A87: 02/2025 | B87: ='Diferenças'!D90 | C87: ='Diferenças'!M90 | D87: ='Diferenças'!N90 | E87: =C87+D87 | F87: =ROUND(E87*'Parâmetros'!$B$21/100,2)
A88: Totais: | B88: =SUM(B12:B87) | C88: =SUM(C12:C87) | D88: =SUM(D12:D87) | E88: =SUM(E12:E87) | F88: =SUM(F12:F87)
A90: Sobre a Base Atualizada: | B90: =ROUND(C88*'Parâmetros'!$B$21/100,2)
A91: Sobre os Juros: | B91: =ROUND(D88*'Parâmetros'!$B$21/100,2)
A92: Valor Fixo: | B92: ='Parâmetros'!$B$23
A93: Total Geral de Honorários: | B93: =B90+B91+B92

Sheet IR (RRA)
A1: Informações para Imposto de Renda (Rendimentos Recebidos Acumuladamente)
A2: Nome do Segurado: | B2: SEGURADO EXEMPLO | D2: NIT: | E2: 000.00000.00-0
A3: CPF: | B3: 000.000.000-00 | D3: Data de Nascimento: | E3: 13/08/1976
A4: Sexo: | B4: Masculino | D4: Nº do Benefício: | E4: 000.000.000-0
A5: Espécie do Benefício: | B5: 46 - Aposentadoria Especial | D5: Nº do Processo: | E5: 0000000-00.2021.4.01.3800
A6: Início do Benefício (DIB): | B6: 16/10/2019 | D6: Data da Atualização: | E6: 08/05/2025
A7: Ajuizamento: | B7: 21/01/2021 | D7: Data da Prescrição: | E7: 16/10/2019
B9: Valor | C9: Meses
A10: Anos-base anteriores | B10: =SUMIFS('Diferenças'!$L$15:$L$90,'Diferenças'!$O$15:$O$90,"<2025") | C10: 69
A11: Ano-base atual (2025) | B11: =SUMIFS('Diferenças'!$L$15:$L$90,'Diferenças'!$O$15:$O$90,2025) | C11: 2
A12: Total | B12: =B10+B11 | C12: 71
A14: Meses: competências mensais + 1 mês por ano com 13º (art. 12-A da Lei 7.713/88).

Sheet Índices
A1: Índices mensais utilizados (%)
A3: Competência | B3: INPC | C3: JUROS MORA | D3: SELIC
A4: 10/2019 | B4: 0.04
A5: 11/2019 | B5: 0.54
A6: 12/2019 | B6: 1.22
A7: 01/2020 | B7: 0.19
A8: 02/2020 | B8: 0.17
A9: 03/2020 | B9: 0.18
A10: 04/2020 | B10: -0.23
A11: 05/2020 | B11: -0.25
A12: 06/2020 | B12: 0.3
A13: 07/2020 | B13: 0.44
A14: 08/2020 | B14: 0.36
A15: 09/2020 | B15: 0.87
... A27: 09/2021 | B27: 1.2
A28: 10/2021 | B28: 1.16 | C28: 0.3575
A29: 11/2021 | B29: 0.84 | C29: 0.4412
A30: 12/2021 | D30: 0.77
A31: 01/2022 | D31: 0.73
A32: 02/2022 | D32: 0.76
A33: 03/2022 | D33: 0.93
A34: 04/2022 | D34: 0.83
A35: 05/2022 | D35: 1.03
A36: 06/2022 | D36: 1.02
A37: 07/2022 | D37: 1.03
A38: 08/2022 | D38: 1.17
A39: 09/2022 | D39: 1.07
A40: 10/2022 | D40: 1.02
A41: 11/2022 | D41: 1.02
... A70: 04/2025 | D70: 1.06
A72: Fontes: IBGE/BCB-SGS (INPC 188, IGP-DI 190, IPCA-E 10764, SELIC 4390, meta SELIC 432) e Manual de Cálculos da Justiça Federal.
