Workbook

Sheet Resumo
A1: Resumo do Cálculo
A2: Nome do Segurado: | B2: JOSE EXEMPLO DA SILVA | D2: NIT: | E2: 111.22222.33-4
A3: CPF: | B3: 111.222.333-44 | D3: Data de Nascimento: | E3: 10/05/1962
A4: Sexo: | B4: Masculino | D4: Nº do Benefício:
A5: Espécie do Benefício: | B5: 42 - Aposentadoria por Tempo de Contribuição | D5: Nº do Processo: | E5: 0000000-00.2024.4.01.3800
A6: Início do Benefício (DIB): | B6: 01/03/2024 | D6: Data da Atualização: | E6: 15/09/2026
A7: Ajuizamento: | B7: 10/06/2024 | D7: Data da Prescrição: | E7: 01/03/2024
A9: Renda Mensal Corrigida até 15/09/2026: | B9: ='Diferenças'!B54
A10: Principal: | B10: ='Diferenças'!D52
A11: Correção Monetária: | B11: ='Diferenças'!R52-'Diferenças'!D52
A12: Total Atualizado: | B12: ='Diferenças'!R52
A13: Valor dos Juros: | B13: ='Diferenças'!S52
A14: (-) Acordo/Deságio: | B14: ='Parâmetros'!$B$24
A15: Total Atualizado + Valor dos Juros - Valor Acordo: | B15: =B12+B13-B14
A16: Honorários Sobre a Base de Cálculo Atualizada: | B16: ='Honorários'!$B$45
A17: Honorários Sobre os Juros da Base de Cálculo: | B17: ='Honorários'!$B$46
A18: Valor Fixo de Honorários: | B18: ='Honorários'!$B$47
A19: Total Atualizado de Honorários: | B19: ='Honorários'!$B$48
A20: Multa: | B20: ='Parâmetros'!$B$25
A21: Dano Moral/Material: | B21: ='Parâmetros'!$B$26
A22: Total Geral: | B22: =B15+B19+B20+B21
A23: Total geral atualizado até 15/09/2026
A24: O valor equivale a (salários mínimos): | B24: =ROUND(B22/'Parâmetros'!$B$27,2)
A26: Valor da causa (art. 292, §§ 1º e 2º, do CPC)
A27: Parcelas vencidas (atualizadas + juros): | B27: =B15
A28: 12 parcelas vincendas (12 × R.M.A.): | B28: =ROUND(12*'Diferenças'!B54,2)
A29: Valor da causa: | B29: =B27+B28
A30: Limite do JEF (60 salários mínimos): | B30: =ROUND(60*'Parâmetros'!$B$27,2)
A31: Competência: | B31: =IF(B29<=B30,"Juizado Especial Federal","Vara Federal (ou renúncia ao excedente)")
A34: Cristiano da Silva Ottone OAB/MG 152.214

Sheet Parâmetros
A1: Parâmetros do cálculo (células amarelas podem ser editadas)
A3: Nome do segurado | B3: JOSE EXEMPLO DA SILVA
A4: NIT | B4: 111.22222.33-4
A5: CPF | B5: 111.222.333-44
A6: Data de nascimento | B6: 10/05/1962
A7: Sexo | B7: M
A8: Nº do benefício
A9: Espécie | B9: 42 - Aposentadoria por Tempo de Contribuição
A10: DER | B10: 01/03/2024
A11: DIB | B11: 01/03/2024
A12: RMI (renda mensal inicial) | B12: 4626.87
A13: Nº do processo | B13: 0000000-00.2024.4.01.3800
A14: Inscrição no INSS
A15: Ajuizamento | B15: 10/06/2024
A16: Citação (início dos juros de mora) | B16: 01/08/2024
A17: Data da prescrição quinquenal | B17: 01/03/2024
A18: Data da atualização | B18: 15/09/2026
A19: Diferenças desde | B19: 01/03/2024
A20: Diferenças até | B20: 31/08/2026
A21: Honorários (%) | B21: 10
A22: Honorários: parcelas até (Súmula 111/STJ) | B22: 30/04/2026
A23: Honorários: valor fixo | B23: 0
A24: (-) Acordo/Deságio | B24: 0
A25: Multa | B25: 0
A26: Dano moral/material | B26: 0
A27: Salário mínimo na data da atualização | B27: 1621
A28: Índice de correção | B28: INPC
A29: Responsável pelo cálculo | B29: Cristiano da Silva Ottone
A30: OAB | B30: OAB/MG 152.214

Sheet Tempo de Contribuição
A1: Tempo de Contribuição e Carência
A2: Nome do Segurado: | B2: JOSE EXEMPLO DA SILVA | D2: NIT: | E2: 111.22222.33-4
A3: CPF: | B3: 111.222.333-44 | D3: Data de Nascimento: | E3: 10/05/1962
A4: Sexo: | B4: Masculino | D4: Nº do Benefício:
A5: Espécie do Benefício: | B5: 42 - Aposentadoria por Tempo de Contribuição | D5: Nº do Processo: | E5: 0000000-00.2024.4.01.3800
A7: Seq. | B7: Empregador / Origem | C7: Tipo | D7: Início | E7: Fim | F7: Especial | G7: Tempo (a/m/d) | H7: Carência? | I7: Computado?
A8: 1 | B8: METALURGICA EXEMPLO LTDA | C8: Empregado ou Agente Público | D8: 01/03/1984 | E8: 30/06/1998 | F8: 25 anos | G8: 14a 4m 0d | H8: sim | I8: sim
A9: 2 | B9: COMERCIO EXEMPLO S.A. | C9: Empregado ou Agente Público | D9: 01/08/1998 | E9: 30/06/2019 | G9: 20a 11m 0d | H9: sim | I9: sim
A10: 3 | B10: Recolhimento | C10: Contribuinte Individual | D10: 01/07/2019 | E10: 31/12/2020 | G10: 1a 6m 0d | H10: sim | I10: sim
B12: Tempo até 13/11/2019 (com conversão do especial) | G12: 41a 4m 7d
B13: Tempo até a DER (com conversão até 13/11/2019) | G13: 42a 5m 24d
B14: Tempo até a DER (sem conversão) | G14: 36a 9m 0d
B15: Tempo especial até a DER | G15: 14a 4m 0d
B16: Carência até a DER (meses) | G16: 441
B17: Idade na DER | G17: 61a 9m 20d
B19: Concomitâncias contadas uma vez. Conversão especial→comum só até 13/11/2019 (EC 103/2019, art. 25, §2º). Contagem em ano de 360 / mês de 30 dias.

Sheet Regras EC 103
A1: Regras de Aposentadoria (direito adquirido, transições da EC 103/2019 e regra permanente)
A2: Nome do Segurado: | B2: JOSE EXEMPLO DA SILVA | D2: NIT: | E2: 111.22222.33-4
A3: CPF: | B3: 111.222.333-44 | D3: Data de Nascimento: | E3: 10/05/1962
A4: Sexo: | B4: Masculino | D4: Nº do Benefício:
A5: Espécie do Benefício: | B5: 42 - Aposentadoria por Tempo de Contribuição | D5: Nº do Processo: | E5: 0000000-00.2024.4.01.3800
A7: Regra | B7: Fundamento | C7: Cumpre na DER? | D7: Data em que cumpre | E7: Requisitos na DER | F7: Requisitos na data | G7: DIB considerada | H7: Média | I7: Coef. (%) | J7: Fator prev. | K7: RMI
A8: Direito adquirido - ATC (Lei 8.213/91, art. 52 e ss.) | B8: EC 103/2019, art. 3º | C8: SIM | D8: 01/03/2024 | E8: TC 41a 4m 7d (mín. 35a); carência 428/180 | F8: TC 41a 4m 7d (mín. 35a); carência 428/180 | G8: 01/03/2024 | H8: 4557.77 | I8: 100 | J8: 1.0109 | K8: 4607.45
A9: Direito adquirido - aposentadoria por idade | B9: EC 103/2019, art. 3º; Lei 8.213/91, art. 48 | C9: não | D9: — | E9: idade 57a 6m 3d (mín. 65a); carência 428/180 | F9: idade 57a 6m 3d (mín. 65a); carência 428/180
A10: Direito adquirido - aposentadoria especial (25 anos) | B10: EC 103/2019, art. 3º; Lei 8.213/91, art. 57 | C10: não | D10: — | E10: tempo especial 14a 4m 0d (mín. 25a); carência 428/180 | F10: tempo especial 14a 4m 0d (mín. 25a); carência 428/180
A11: Transição - pontos | B11: EC 103/2019, art. 15 | C11: SIM | D11: 01/03/2024 | E11: TC 42a 5m 24d; pontos 104.29 (mín. 101); carência 441/180 | F11: TC 42a 5m 24d; pontos 104.29 (mín. 101); carência 441/180 | G11: 01/03/2024 | H11: 4336.74 | I11: 104 | K11: 4510.21
A12: Transição - idade mínima progressiva | B12: EC 103/2019, art. 16 | C12: não | D12: 10/11/2026 | E12: TC 42a 5m 24d; idade 61a 9m 20d (mín. 63.5); carência 441/180 | F12: TC 45a 2m 3d; idade 64a 6m 0d (mín. 64.5); carência 474/180 | G12: 10/11/2026 | H12: 4336.74 | I12: 104 | K12: 4510.21
A13: Transição - pedágio 50% | B13: EC 103/2019, art. 17 | C13: SIM | D13: 01/03/2024 | E13: TC em 13/11/2019 41a 4m 7d (precisa > 33a); TC 42a 5m 24d (mín. 35a 0m 0d); carência 441/180 | F13: TC em 13/11/2019 41a 4m 7d (precisa > 33a); TC 42a 5m 24d (mín. 35a 0m 0d); carência 441/180 | G13: 01/03/2024 | H13: 4336.74 | I13: 100 | J13: 1.0669 | K13: 4626.87
A14: Transição - pedágio 100% | B14: EC 103/2019, art. 20 | C14: SIM | D14: 01/03/2024 | E14: idade 61a 9m 20d (mín. 60a); TC 42a 5m 24d (mín. 35a 0m 0d); carência 441/180 | F14: idade 61a 9m 20d (mín. 60a); TC 42a 5m 24d (mín. 35a 0m 0d); carência 441/180 | G14: 01/03/2024 | H14: 4336.74 | I14: 100 | K14: 4336.74
A15: Transição - aposentadoria por idade | B15: EC 103/2019, art. 18 | C15: não | D15: 10/05/2027 | E15: idade 61a 9m 20d (mín. 65); TC 42a 5m 24d (mín. 15a); carência 441/180 | F15: idade 65a 0m 0d (mín. 65); TC 45a 8m 3d (mín. 15a); carência 480/180 | G15: 10/05/2027 | H15: 4336.74 | I15: 104 | K15: 4510.21
A16: Transição - aposentadoria especial (25 anos) | B16: EC 103/2019, art. 21 | C16: não | D16: — | E16: tempo especial 14a 4m 0d (mín. 25a); pontos 98.56 (mín. 86); carência 441/180 | F16: tempo especial 14a 4m 0d (mín. 25a); pontos 98.56 (mín. 86); carência 441/180
A17: Regra permanente (programada) | B17: EC 103/2019, art. 19 | C17: não | D17: 10/05/2027 | E17: idade 61a 9m 20d (mín. 65a); TC 42a 5m 24d (mín. 20a); carência 441/180 | F17: idade 65a 0m 0d (mín. 65a); TC 45a 8m 3d (mín. 20a); carência 480/180 | G17: 10/05/2027 | H17: 4336.74 | I17: 104 | K17: 4510.21
A19: Regra mais vantajosa: Transição - pedágio 50%
A20: Datas posteriores à DER supõem contribuições contínuas após o último vínculo (reafirmação da DER, Tema 995/STJ).

Sheet Salários e RMI
A1: Salários de Contribuição (PBC desde 07/1994) e Média
A2: Nome do Segurado: | B2: JOSE EXEMPLO DA SILVA | D2: NIT: | E2: 111.22222.33-4
A3: CPF: | B3: 111.222.333-44 | D3: Data de Nascimento: | E3: 10/05/1962
A4: Sexo: | B4: Masculino | D4: Nº do Benefício:
A5: Espécie do Benefício: | B5: 42 - Aposentadoria por Tempo de Contribuição | D5: Nº do Processo: | E5: 0000000-00.2024.4.01.3800
A7: Competência | B7: Salário (CNIS) | C7: Teto | D7: Salário limitado | E7: Fator de correção | F7: Salário corrigido
A8: 07/1994 | B8: 1500 | D8: =IF(C8="",B8,MIN(B8,C8)) | F8: 2850
A9: 08/1994 | B9: 1500 | D9: =IF(C9="",B9,MIN(B9,C9)) | F9: 2850
A10: 09/1994 | B10: 1500 | D10: =IF(C10="",B10,MIN(B10,C10)) | F10: 2850
A11: 10/1994 | B11: 1500 | D11: =IF(C11="",B11,MIN(B11,C11)) | F11: 2850
A12: 11/1994 | B12: 1500 | D12: =IF(C12="",B12,MIN(B12,C12)) | F12: 2850
A13: 12/1994 | B13: 1500 | D13: =IF(C13="",B13,MIN(B13,C13)) | F13: 2850
A14: 01/1995 | B14: 1580 | D14: =IF(C14="",B14,MIN(B14,C14)) | F14: 2962
A15: 02/1995 | B15: 1580 | D15: =IF(C15="",B15,MIN(B15,C15)) | F15: 2962
A16: 03/1995 | B16: 1580 | D16: =IF(C16="",B16,MIN(B16,C16)) | F16: 2962
A17: 04/1995 | B17: 1580 | D17: =IF(C17="",B17,MIN(B17,C17)) | F17: 2962
A18: 05/1995 | B18: 1580 | D18: =IF(C18="",B18,MIN(B18,C18)) | F18: 2962
A19: 06/1995 | B19: 1580 | D19: =IF(C19="",B19,MIN(B19,C19)) | F19: 2962
... A252: 12/2014 | B252: 3100 | D252: =IF(C252="",B252,MIN(B252,C252)) | F252: 5090
A253: 01/2015 | B253: 3180 | C253: 4663.75 | D253: =IF(C253="",B253,MIN(B253,C253)) | F253: 5202
A254: 02/2015 | B254: 3180 | C254: 4663.75 | D254: =IF(C254="",B254,MIN(B254,C254)) | F254: 5202
A255: 03/2015 | B255: 3180 | C255: 4663.75 | D255: =IF(C255="",B255,MIN(B255,C255)) | F255: 5202
A256: 04/2015 | B256: 3180 | C256: 4663.75 | D256: =IF(C256="",B256,MIN(B256,C256)) | F256: 5202
A257: 05/2015 | B257: 3180 | C257: 4663.75 | D257: =IF(C257="",B257,MIN(B257,C257)) | F257: 5202
A258: 06/2015 | B258: 3180 | C258: 4663.75 | D258: =IF(C258="",B258,MIN(B258,C258)) | F258: 5202
A259: 07/2015 | B259: 3180 | C259: 4663.75 | D259: =IF(C259="",B259,MIN(B259,C259)) | F259: 5202
A260: 08/2015 | B260: 3180 | C260: 4663.75 | D260: =IF(C260="",B260,MIN(B260,C260)) | F260: 5202
A261: 09/2015 | B261: 3180 | C261: 4663.75 | D261: =IF(C261="",B261,MIN(B261,C261)) | F261: 5202
A262: 10/2015 | B262: 3180 | C262: 4663.75 | D262: =IF(C262="",B262,MIN(B262,C262)) | F262: 5202
A263: 11/2015 | B263: 3180 | C263: 4663.75 | D263: =IF(C263="",B263,MIN(B263,C263)) | F263: 5202
A264: 12/2015 | B264: 3180 | C264: 4663.75 | D264: =IF(C264="",B264,MIN(B264,C264)) | F264: 5202
... A324: 12/2020 | B324: 3580 | C324: 6101.06 | D324: =IF(C324="",B324,MIN(B324,C324)) | F324: 5762
A326: Média de 100% dos salários (art. 26 da EC 103/2019): | F326: =IFERROR(ROUND(AVERAGE(F8:F324),2),0)
A327: Quantidade de salários: | F327: =COUNT(F8:F324)
A329: Fatores: índices de correção dos salários de contribuição (INPC; IGP-DI de 05/1996 a 08/2006 pela tabela do Manual CJF). Confira com a carta de concessão.

Sheet Competências s-SC
A1: Competências Sem Salários de Contribuição
A2: Nome do Segurado: | B2: JOSE EXEMPLO DA SILVA | D2: NIT: | E2: 111.22222.33-4
A3: CPF: | B3: 111.222.333-44 | D3: Data de Nascimento: | E3: 10/05/1962
A4: Sexo: | B4: Masculino | D4: Nº do Benefício:
A5: Espécie do Benefício: | B5: 42 - Aposentadoria por Tempo de Contribuição | D5: Nº do Processo: | E5: 0000000-00.2024.4.01.3800
A7: Competência | B7: Empresa | C7: Data
A8: 03/1984 | B8: METALURGICA EXEMPLO LTDA | C8: 01/03/1984
A9: 04/1984 | B9: METALURGICA EXEMPLO LTDA | C9: 01/04/1984
A10: 05/1984 | B10: METALURGICA EXEMPLO LTDA | C10: 01/05/1984
A11: 06/1984 | B11: METALURGICA EXEMPLO LTDA | C11: 01/06/1984
A12: 07/1984 | B12: METALURGICA EXEMPLO LTDA | C12: 01/07/1984
A13: 08/1984 | B13: METALURGICA EXEMPLO LTDA | C13: 01/08/1984
A14: 09/1984 | B14: METALURGICA EXEMPLO LTDA | C14: 01/09/1984
A15: 10/1984 | B15: METALURGICA EXEMPLO LTDA | C15: 01/10/1984
A16: 11/1984 | B16: METALURGICA EXEMPLO LTDA | C16: 01/11/1984
A17: 12/1984 | B17: METALURGICA EXEMPLO LTDA | C17: 01/12/1984
A18: 01/1985 | B18: METALURGICA EXEMPLO LTDA | C18: 01/01/1985
... A131: 06/1994 | B131: METALURGICA EXEMPLO LTDA | C131: 01/06/1994

Sheet Evolução RMI
A1: Relatório da Evolução da R.M.I.
A2: Nome do Segurado: | B2: JOSE EXEMPLO DA SILVA | D2: NIT: | E2: 111.22222.33-4
A3: CPF: | B3: 111.222.333-44 | D3: Data de Nascimento: | E3: 10/05/1962
A4: Sexo: | B4: Masculino | D4: Nº do Benefício:
A5: Espécie do Benefício: | B5: 42 - Aposentadoria por Tempo de Contribuição | D5: Nº do Processo: | E5: 0000000-00.2024.4.01.3800
A6: Início do Benefício (DIB): | B6: 01/03/2024 | D6: Data da Atualização: | E6: 15/09/2026
A7: Ajuizamento: | B7: 10/06/2024 | D7: Data da Prescrição: | E7: 01/03/2024
A9: Data | B9: Valor do Benefício | C9: Reajuste (%) | D9: Teto do Benefício | E9: Salário Mínimo | F9: Benefício Mensal | G9: Fração (pró-rata) | H9: Benefício Considerado
A10: 03/2024 | B10: ='Parâmetros'!$B$12 | D10: 7786.02 | E10: 1412 | F10: =MAX(E10,MIN(D10,IF(C10="",B10,TRUNC(B10*(1+C10/100),2)))) | G10: 1 | H10: =TRUNC(F10*G10,2)
A11: 04/2024 | B11: =F10 | D11: 7786.02 | E11: 1412 | F11: =MAX(E11,MIN(D11,IF(C11="",B11,TRUNC(B11*(1+C11/100),2)))) | G11: 1 | H11: =TRUNC(F11*G11,2)
A12: 05/2024 | B12: =F11 | D12: 7786.02 | E12: 1412 | F12: =MAX(E12,MIN(D12,IF(C12="",B12,TRUNC(B12*(1+C12/100),2)))) | G12: 1 | H12: =TRUNC(F12*G12,2)
A13: 06/2024 | B13: =F12 | D13: 7786.02 | E13: 1412 | F13: =MAX(E13,MIN(D13,IF(C13="",B13,TRUNC(B13*(1+C13/100),2)))) | G13: 1 | H13: =TRUNC(F13*G13,2)
A14: 07/2024 | B14: =F13 | D14: 7786.02 | E14: 1412 | F14: =MAX(E14,MIN(D14,IF(C14="",B14,TRUNC(B14*(1+C14/100),2)))) | G14: 1 | H14: =TRUNC(F14*G14,2)
A15: 08/2024 | B15: =F14 | D15: 7786.02 | E15: 1412 | F15: =MAX(E15,MIN(D15,IF(C15="",B15,TRUNC(B15*(1+C15/100),2)))) | G15: 1 | H15: =TRUNC(F15*G15,2)
A16: 09/2024 | B16: =F15 | D16: 7786.02 | E16: 1412 | F16: =MAX(E16,MIN(D16,IF(C16="",B16,TRUNC(B16*(1+C16/100),2)))) | G16: 1 | H16: =TRUNC(F16*G16,2)
A17: 10/2024 | B17: =F16 | D17: 7786.02 | E17: 1412 | F17: =MAX(E17,MIN(D17,IF(C17="",B17,TRUNC(B17*(1+C17/100),2)))) | G17: 1 | H17: =TRUNC(F17*G17,2)
A18: 11/2024 | B18: =F17 | D18: 7786.02 | E18: 1412 | F18: =MAX(E18,MIN(D18,IF(C18="",B18,TRUNC(B18*(1+C18/100),2)))) | G18: 1 | H18: =TRUNC(F18*G18,2)
A19: 12/2024 | B19: =F18 | D19: 7786.02 | E19: 1412 | F19: =MAX(E19,MIN(D19,IF(C19="",B19,TRUNC(B19*(1+C19/100),2)))) | G19: 1 | H19: =TRUNC(F19*G19,2)
A20: 01/2025 | B20: =F19 | C20: 4.07 | D20: 8157.41 | E20: 1518 | F20: =MAX(E20,MIN(D20,IF(C20="",B20,TRUNC(B20*(1+C20/100),2)))) | G20: 1 | H20: =TRUNC(F20*G20,2)
A21: 02/2025 | B21: =F20 | D21: 8157.41 | E21: 1518 | F21: =MAX(E21,MIN(D21,IF(C21="",B21,TRUNC(B21*(1+C21/100),2)))) | G21: 1 | H21: =TRUNC(F21*G21,2)
A22: 03/2025 | B22: =F21 | D22: 8157.41 | E22: 1518 | F22: =MAX(E22,MIN(D22,IF(C22="",B22,TRUNC(B22*(1+C22/100),2)))) | G22: 1 | H22: =TRUNC(F22*G22,2)
A23: 04/2025 | B23: =F22 | D23: 8157.41 | E23: 1518 | F23: =MAX(E23,MIN(D23,IF(C23="",B23,TRUNC(B23*(1+C23/100),2)))) | G23: 1 | H23: =TRUNC(F23*G23,2)
A24: 05/2025 | B24: =F23 | D24: 8157.41 | E24: 1518 | F24: =MAX(E24,MIN(D24,IF(C24="",B24,TRUNC(B24*(1+C24/100),2)))) | G24: 1 | H24: =TRUNC(F24*G24,2)
A25: 06/2025 | B25: =F24 | D25: 8157.41 | E25: 1518 | F25: =MAX(E25,MIN(D25,IF(C25="",B25,TRUNC(B25*(1+C25/100),2)))) | G25: 1 | H25: =TRUNC(F25*G25,2)
A26: 07/2025 | B26: =F25 | D26: 8157.41 | E26: 1518 | F26: =MAX(E26,MIN(D26,IF(C26="",B26,TRUNC(B26*(1+C26/100),2)))) | G26: 1 | H26: =TRUNC(F26*G26,2)
A27: 08/2025 | B27: =F26 | D27: 8157.41 | E27: 1518 | F27: =MAX(E27,MIN(D27,IF(C27="",B27,TRUNC(B27*(1+C27/100),2)))) | G27: 1 | H27: =TRUNC(F27*G27,2)
A28: 09/2025 | B28: =F27 | D28: 8157.41 | E28: 1518 | F28: =MAX(E28,MIN(D28,IF(C28="",B28,TRUNC(B28*(1+C28/100),2)))) | G28: 1 | H28: =TRUNC(F28*G28,2)
A29: 10/2025 | B29: =F28 | D29: 8157.41 | E29: 1518 | F29: =MAX(E29,MIN(D29,IF(C29="",B29,TRUNC(B29*(1+C29/100),2)))) | G29: 1 | H29: =TRUNC(F29*G29,2)
A30: 11/2025 | B30: =F29 | D30: 8157.41 | E30: 1518 | F30: =MAX(E30,MIN(D30,IF(C30="",B30,TRUNC(B30*(1+C30/100),2)))) | G30: 1 | H30: =TRUNC(F30*G30,2)
A31: 12/2025 | B31: =F30 | D31: 8157.41 | E31: 1518 | F31: =MAX(E31,MIN(D31,IF(C31="",B31,TRUNC(B31*(1+C31/100),2)))) | G31: 1 | H31: =TRUNC(F31*G31,2)
A32: 01/2026 | B32: =F31 | C32: 3.9 | D32: 8475.55 | E32: 1621 | F32: =MAX(E32,MIN(D32,IF(C32="",B32,TRUNC(B32*(1+C32/100),2)))) | G32: 1 | H32: =TRUNC(F32*G32,2)
A33: 02/2026 | B33: =F32 | D33: 8475.55 | E33: 1621 | F33: =MAX(E33,MIN(D33,IF(C33="",B33,TRUNC(B33*(1+C33/100),2)))) | G33: 1 | H33: =TRUNC(F33*G33,2)
A34: 03/2026 | B34: =F33 | D34: 8475.55 | E34: 1621 | F34: =MAX(E34,MIN(D34,IF(C34="",B34,TRUNC(B34*(1+C34/100),2)))) | G34: 1 | H34: =TRUNC(F34*G34,2)
A35: 04/2026 | B35: =F34 | D35: 8475.55 | E35: 1621 | F35: =MAX(E35,MIN(D35,IF(C35="",B35,TRUNC(B35*(1+C35/100),2)))) | G35: 1 | H35: =TRUNC(F35*G35,2)
A36: 05/2026 | B36: =F35 | D36: 8475.55 | E36: 1621 | F36: =MAX(E36,MIN(D36,IF(C36="",B36,TRUNC(B36*(1+C36/100),2)))) | G36: 1 | H36: =TRUNC(F36*G36,2)
A37: 06/2026 | B37: =F36 | D37: 8475.55 | E37: 1621 | F37: =MAX(E37,MIN(D37,IF(C37="",B37,TRUNC(B37*(1+C37/100),2)))) | G37: 1 | H37: =TRUNC(F37*G37,2)
A38: 07/2026 | B38: =F37 | D38: 8475.55 | E38: 1621 | F38: =MAX(E38,MIN(D38,IF(C38="",B38,TRUNC(B38*(1+C38/100),2)))) | G38: 1 | H38: =TRUNC(F38*G38,2)
A39: 08/2026 | B39: =F38 | D39: 8475.55 | E39: 1621 | F39: =MAX(E39,MIN(D39,IF(C39="",B39,TRUNC(B39*(1+C39/100),2)))) | G39: 1 | H39: =TRUNC(F39*G39,2)
A40: 09/2026 | B40: =F39 | D40: 8475.55 | E40: 1621 | F40: =MAX(E40,MIN(D40,IF(C40="",B40,TRUNC(B40*(1+C40/100),2)))) | G40: 1 | H40: =TRUNC(F40*G40,2)
A42: Nova R.M.A.: | B42: =F40
...

Sheet Diferenças
A1: Relatório das Diferenças Não Recebidas
A2: Nome do Segurado: | B2: JOSE EXEMPLO DA SILVA | D2: NIT: | E2: 111.22222.33-4
A3: CPF: | B3: 111.222.333-44 | D3: Data de Nascimento: | E3: 10/05/1962
A4: Sexo: | B4: Masculino | D4: Nº do Benefício:
A5: Espécie do Benefício: | B5: 42 - Aposentadoria por Tempo de Contribuição | D5: Nº do Processo: | E5: 0000000-00.2024.4.01.3800
A6: Início do Benefício (DIB): | B6: 01/03/2024 | D6: Data da Atualização: | E6: 15/09/2026
A7: Ajuizamento: | B7: 10/06/2024 | D7: Data da Prescrição: | E7: 01/03/2024
A9: Correção monetária: Tabela da Justiça Federal (INPC; IGP-DI de 05/1996 a 08/2006), pró-rata no 1º mês, até 11/2021.
A10: Juros de mora a partir da citação: 1% a.m. até 06/2009; 0,5% a.m. até 04/2012; juros da poupança (Lei 12.703/2012) até 11/2021 — sem capitalização.
A11: De 12/2021 a 08/2025: SELIC acumulada (simples), uma única vez, substituindo correção e juros (EC 113/2021, art. 3º; Tema 1.419/STF).
A12: A partir de 09/2025: correção pelo INPC e juros de mora pela taxa legal (SELIC com dedução do INPC; art. 406 do CC) — Manual de Cálculos da JF, Res. CJF 990/2026 (EC 136/2025).
A13: Diferenças consideradas de 01/03/2024 a 31/08/2026.
A15: Data | B15: Valor do Benefício | C15: Valor Já Recebido | D15: Diferença | E15: Índice de Atualização | F15: Valor Atualizado | G15: % Juros | H15: Valor dos Juros | I15: Valor Atualizado + Juros | J15: % Selic | K15: Valor da Selic | L15: Total até 08/2025 | M15: Índice INPC desde 09/2025 | N15: Valor Corrigido | O15: % Taxa Legal | P15: Juros Taxa Legal | Q15: Total Atualizado | R15: Base atualizada | S15: Juros (todos) | T15: Ano | U15: Tipo
A16: 03/2024 | B16: ='Evolução RMI'!H10 | C16: 0 | D16: =B16-C16 | E16: 1 | F16: =ROUND(D16*E16,2) | G16: 0 | H16: =ROUND(F16*G16/100,2) | I16: =F16+H16 | J16: 18 | K16: =ROUND(I16*J16/100,2) | L16: =I16+K16 | M16: 1.0490702 | N16: =ROUND(L16*M16,2) | O16: 7.2 | P16: =ROUND(N16*O16/100,2) | Q16: =N16+P16 | R16: =F16+N16-L16 | S16: =H16+K16+P16 | T16: 2024 | U16: mensal
A17: 04/2024 | B17: ='Evolução RMI'!H11 | C17: 0 | D17: =B17-C17 | E17: 1 | F17: =ROUND(D17*E17,2) | G17: 0 | H17: =ROUND(F17*G17/100,2) | I17: =F17+H17 | J17: 17 | K17: =ROUND(I17*J17/100,2) | L17: =I17+K17 | M17: 1.0490702 | N17: =ROUND(L17*M17,2) | O17: 7.2 | P17: =ROUND(N17*O17/100,2) | Q17: =N17+P17 | R17: =F17+N17-L17 | S17: =H17+K17+P17 | T17: 2024 | U17: mensal
A18: 13º | B18: =TRUNC('Evolução RMI'!F11/2,2) | C18: 0 | D18: =B18-C18 | E18: 1 | F18: =ROUND(D18*E18,2) | G18: 0 | H18: =ROUND(F18*G18/100,2) | I18: =F18+H18 | J18: 17 | K18: =ROUND(I18*J18/100,2) | L18: =I18+K18 | M18: 1.0490702 | N18: =ROUND(L18*M18,2) | O18: 7.2 | P18: =ROUND(N18*O18/100,2) | Q18: =N18+P18 | R18: =F18+N18-L18 | S18: =H18+K18+P18 | T18: 2024 | U18: 13º
A19: 05/2024 | B19: ='Evolução RMI'!H12 | C19: 0 | D19: =B19-C19 | E19: 1 | F19: =ROUND(D19*E19,2) | G19: 0 | H19: =ROUND(F19*G19/100,2) | I19: =F19+H19 | J19: 16 | K19: =ROUND(I19*J19/100,2) | L19: =I19+K19 | M19: 1.0490702 | N19: =ROUND(L19*M19,2) | O19: 7.2 | P19: =ROUND(N19*O19/100,2) | Q19: =N19+P19 | R19: =F19+N19-L19 | S19: =H19+K19+P19 | T19: 2024 | U19: mensal
A20: 13º | B20: =TRUNC('Evolução RMI'!F12*10/12-'Evolução RMI'!F11/2,2) | C20: 0 | D20: =B20-C20 | E20: 1 | F20: =ROUND(D20*E20,2) | G20: 0 | H20: =ROUND(F20*G20/100,2) | I20: =F20+H20 | J20: 16 | K20: =ROUND(I20*J20/100,2) | L20: =I20+K20 | M20: 1.0490702 | N20: =ROUND(L20*M20,2) | O20: 7.2 | P20: =ROUND(N20*O20/100,2) | Q20: =N20+P20 | R20: =F20+N20-L20 | S20: =H20+K20+P20 | T20: 2024 | U20: 13º
A21: 06/2024 | B21: ='Evolução RMI'!H13 | C21: 0 | D21: =B21-C21 | E21: 1 | F21: =ROUND(D21*E21,2) | G21: 0 | H21: =ROUND(F21*G21/100,2) | I21: =F21+H21 | J21: 15 | K21: =ROUND(I21*J21/100,2) | L21: =I21+K21 | M21: 1.0490702 | N21: =ROUND(L21*M21,2) | O21: 7.2 | P21: =ROUND(N21*O21/100,2) | Q21: =N21+P21 | R21: =F21+N21-L21 | S21: =H21+K21+P21 | T21: 2024 | U21: mensal
A22: 07/2024 | B22: ='Evolução RMI'!H14 | C22: 0 | D22: =B22-C22 | E22: 1 | F22: =ROUND(D22*E22,2) | G22: 0 | H22: =ROUND(F22*G22/100,2) | I22: =F22+H22 | J22: 14 | K22: =ROUND(I22*J22/100,2) | L22: =I22+K22 | M22: 1.0490702 | N22: =ROUND(L22*M22,2) | O22: 7.2 | P22: =ROUND(N22*O22/100,2) | Q22: =N22+P22 | R22: =F22+N22-L22 | S22: =H22+K22+P22 | T22: 2024 | U22: mensal
A23: 08/2024 | B23: ='Evolução RMI'!H15 | C23: 0 | D23: =B23-C23 | E23: 1 | F23: =ROUND(D23*E23,2) | G23: 0 | H23: =ROUND(F23*G23/100,2) | I23: =F23+H23 | J23: 13 | K23: =ROUND(I23*J23/100,2) | L23: =I23+K23 | M23: 1.0490702 | N23: =ROUND(L23*M23,2) | O23: 7.2 | P23: =ROUND(N23*O23/100,2) | Q23: =N23+P23 | R23: =F23+N23-L23 | S23: =H23+K23+P23 | T23: 2024 | U23: mensal
A24: 09/2024 | B24: ='Evolução RMI'!H16 | C24: 0 | D24: =B24-C24 | E24: 1 | F24: =ROUND(D24*E24,2) | G24: 0 | H24: =ROUND(F24*G24/100,2) | I24: =F24+H24 | J24: 12 | K24: =ROUND(I24*J24/100,2) | L24: =I24+K24 | M24: 1.0490702 | N24: =ROUND(L24*M24,2) | O24: 7.2 | P24: =ROUND(N24*O24/100,2) | Q24: =N24+P24 | R24: =F24+N24-L24 | S24: =H24+K24+P24 | T24: 2024 | U24: mensal
A25: 10/2024 | B25: ='Evolução RMI'!H17 | C25: 0 | D25: =B25-C25 | E25: 1 | F25: =ROUND(D25*E25,2) | G25: 0 | H25: =ROUND(F25*G25/100,2) | I25: =F25+H25 | J25: 11 | K25: =ROUND(I25*J25/100,2) | L25: =I25+K25 | M25: 1.0490702 | N25: =ROUND(L25*M25,2) | O25: 7.2 | P25: =ROUND(N25*O25/100,2) | Q25: =N25+P25 | R25: =F25+N25-L25 | S25: =H25+K25+P25 | T25: 2024 | U25: mensal
A26: 11/2024 | B26: ='Evolução RMI'!H18 | C26: 0 | D26: =B26-C26 | E26: 1 | F26: =ROUND(D26*E26,2) | G26: 0 | H26: =ROUND(F26*G26/100,2) | I26: =F26+H26 | J26: 10 | K26: =ROUND(I26*J26/100,2) | L26: =I26+K26 | M26: 1.0490702 | N26: =ROUND(L26*M26,2) | O26: 7.2 | P26: =ROUND(N26*O26/100,2) | Q26: =N26+P26 | R26: =F26+N26-L26 | S26: =H26+K26+P26 | T26: 2024 | U26: mensal
A27: 12/2024 | B27: ='Evolução RMI'!H19 | C27: 0 | D27: =B27-C27 | E27: 1 | F27: =ROUND(D27*E27,2) | G27: 0 | H27: =ROUND(F27*G27/100,2) | I27: =F27+H27 | J27: 9 | K27: =ROUND(I27*J27/100,2) | L27: =I27+K27 | M27: 1.0490702 | N27: =ROUND(L27*M27,2) | O27: 7.2 | P27: =ROUND(N27*O27/100,2) | Q27: =N27+P27 | R27: =F27+N27-L27 | S27: =H27+K27+P27 | T27: 2024 | U27: mensal
A28: 01/2025 | B28: ='Evolução RMI'!H20 | C28: 0 | D28: =B28-C28 | E28: 1 | F28: =ROUND(D28*E28,2) | G28: 0 | H28: =ROUND(F28*G28/100,2) | I28: =F28+H28 | J28: 8 | K28: =ROUND(I28*J28/100,2) | L28: =I28+K28 | M28: 1.0490702 | N28: =ROUND(L28*M28,2) | O28: 7.2 | P28: =ROUND(N28*O28/100,2) | Q28: =N28+P28 | R28: =F28+N28-L28 | S28: =H28+K28+P28 | T28: 2025 | U28: mensal
A29: 02/2025 | B29: ='Evolução RMI'!H21 | C29: 0 | D29: =B29-C29 | E29: 1 | F29: =ROUND(D29*E29,2) | G29: 0 | H29: =ROUND(F29*G29/100,2) | I29: =F29+H29 | J29: 7 | K29: =ROUND(I29*J29/100,2) | L29: =I29+K29 | M29: 1.0490702 | N29: =ROUND(L29*M29,2) | O29: 7.2 | P29: =ROUND(N29*O29/100,2) | Q29: =N29+P29 | R29: =F29+N29-L29 | S29: =H29+K29+P29 | T29: 2025 | U29: mensal
A30: 03/2025 | B30: ='Evolução RMI'!H22 | C30: 0 | D30: =B30-C30 | E30: 1 | F30: =ROUND(D30*E30,2) | G30: 0 | H30: =ROUND(F30*G30/100,2) | I30: =F30+H30 | J30: 6 | K30: =ROUND(I30*J30/100,2) | L30: =I30+K30 | M30: 1.0490702 | N30: =ROUND(L30*M30,2) | O30: 7.2 | P30: =ROUND(N30*O30/100,2) | Q30: =N30+P30 | R30: =F30+N30-L30 | S30: =H30+K30+P30 | T30: 2025 | U30: mensal
A31: 04/2025 | B31: ='Evolução RMI'!H23 | C31: 0 | D31: =B31-C31 | E31: 1 | F31: =ROUND(D31*E31,2) | G31: 0 | H31: =ROUND(F31*G31/100,2) | I31: =F31+H31 | J31: 5 | K31: =ROUND(I31*J31/100,2) | L31: =I31+K31 | M31: 1.0490702 | N31: =ROUND(L31*M31,2) | O31: 7.2 | P31: =ROUND(N31*O31/100,2) | Q31: =N31+P31 | R31: =F31+N31-L31 | S31: =H31+K31+P31 | T31: 2025 | U31: mensal
A32: 13º | B32: =TRUNC('Evolução RMI'!F23/2,2) | C32: 0 | D32: =B32-C32 | E32: 1 | F32: =ROUND(D32*E32,2) | G32: 0 | H32: =ROUND(F32*G32/100,2) | I32: =F32+H32 | J32: 5 | K32: =ROUND(I32*J32/100,2) | L32: =I32+K32 | M32: 1.0490702 | N32: =ROUND(L32*M32,2) | O32: 7.2 | P32: =ROUND(N32*O32/100,2) | Q32: =N32+P32 | R32: =F32+N32-L32 | S32: =H32+K32+P32 | T32: 2025 | U32: 13º
A33: 05/2025 | B33: ='Evolução RMI'!H24 | C33: 0 | D33: =B33-C33 | E33: 1 | F33: =ROUND(D33*E33,2) | G33: 0 | H33: =ROUND(F33*G33/100,2) | I33: =F33+H33 | J33: 4 | K33: =ROUND(I33*J33/100,2) | L33: =I33+K33 | M33: 1.0490702 | N33: =ROUND(L33*M33,2) | O33: 7.2 | P33: =ROUND(N33*O33/100,2) | Q33: =N33+P33 | R33: =F33+N33-L33 | S33: =H33+K33+P33 | T33: 2025 | U33: mensal
A34: 13º | B34: =TRUNC('Evolução RMI'!F24*12/12-'Evolução RMI'!F23/2,2) | C34: 0 | D34: =B34-C34 | E34: 1 | F34: =ROUND(D34*E34,2) | G34: 0 | H34: =ROUND(F34*G34/100,2) | I34: =F34+H34 | J34: 4 | K34: =ROUND(I34*J34/100,2) | L34: =I34+K34 | M34: 1.0490702 | N34: =ROUND(L34*M34,2) | O34: 7.2 | P34: =ROUND(N34*O34/100,2) | Q34: =N34+P34 | R34: =F34+N34-L34 | S34: =H34+K34+P34 | T34: 2025 | U34: 13º
A35: 06/2025 | B35: ='Evolução RMI'!H25 | C35: 0 | D35: =B35-C35 | E35: 1 | F35: =ROUND(D35*E35,2) | G35: 0 | H35: =ROUND(F35*G35/100,2) | I35: =F35+H35 | J35: 3 | K35: =ROUND(I35*J35/100,2) | L35: =I35+K35 | M35: 1.0490702 | N35: =ROUND(L35*M35,2) | O35: 7.2 | P35: =ROUND(N35*O35/100,2) | Q35: =N35+P35 | R35: =F35+N35-L35 | S35: =H35+K35+P35 | T35: 2025 | U35: mensal
A36: 07/2025 | B36: ='Evolução RMI'!H26 | C36: 0 | D36: =B36-C36 | E36: 1 | F36: =ROUND(D36*E36,2) | G36: 0 | H36: =ROUND(F36*G36/100,2) | I36: =F36+H36 | J36: 2 | K36: =ROUND(I36*J36/100,2) | L36: =I36+K36 | M36: 1.0490702 | N36: =ROUND(L36*M36,2) | O36: 7.2 | P36: =ROUND(N36*O36/100,2) | Q36: =N36+P36 | R36: =F36+N36-L36 | S36: =H36+K36+P36 | T36: 2025 | U36: mensal
A37: 08/2025 | B37: ='Evolução RMI'!H27 | C37: 0 | D37: =B37-C37 | E37: 1 | F37: =ROUND(D37*E37,2) | G37: 0 | H37: =ROUND(F37*G37/100,2) | I37: =F37+H37 | J37: 1 | K37: =ROUND(I37*J37/100,2) | L37: =I37+K37 | M37: 1.0490702 | N37: =ROUND(L37*M37,2) | O37: 7.2 | P37: =ROUND(N37*O37/100,2) | Q37: =N37+P37 | R37: =F37+N37-L37 | S37: =H37+K37+P37 | T37: 2025 | U37: mensal
A38: 09/2025 | B38: ='Evolução RMI'!H28 | C38: 0 | D38: =B38-C38 | E38: 1 | F38: =ROUND(D38*E38,2) | G38: 0 | H38: =ROUND(F38*G38/100,2) | I38: =F38+H38 | J38: 0 | K38: =ROUND(I38*J38/100,2) | L38: =I38+K38 | M38: 1.0490702 | N38: =ROUND(L38*M38,2) | O38: 7.2 | P38: =ROUND(N38*O38/100,2) | Q38: =N38+P38 | R38: =F38+N38-L38 | S38: =H38+K38+P38 | T38: 2025 | U38: mensal
A39: 10/2025 | B39: ='Evolução RMI'!H29 | C39: 0 | D39: =B39-C39 | E39: 1 | F39: =ROUND(D39*E39,2) | G39: 0 | H39: =ROUND(F39*G39/100,2) | I39: =F39+H39 | J39: 0 | K39: =ROUND(I39*J39/100,2) | L39: =I39+K39 | M39: 1.0448906 | N39: =ROUND(L39*M39,2) | O39: 6.6 | P39: =ROUND(N39*O39/100,2) | Q39: =N39+P39 | R39: =F39+N39-L39 | S39: =H39+K39+P39 | T39: 2025 | U39: mensal
A40: 11/2025 | B40: ='Evolução RMI'!H30 | C40: 0 | D40: =B40-C40 | E40: 1 | F40: =ROUND(D40*E40,2) | G40: 0 | H40: =ROUND(F40*G40/100,2) | I40: =F40+H40 | J40: 0 | K40: =ROUND(I40*J40/100,2) | L40: =I40+K40 | M40: 1.0407277 | N40: =ROUND(L40*M40,2) | O40: 6 | P40: =ROUND(N40*O40/100,2) | Q40: =N40+P40 | R40: =F40+N40-L40 | S40: =H40+K40+P40 | T40: 2025 | U40: mensal
A41: 12/2025 | B41: ='Evolução RMI'!H31 | C41: 0 | D41: =B41-C41 | E41: 1 | F41: =ROUND(D41*E41,2) | G41: 0 | H41: =ROUND(F41*G41/100,2) | I41: =F41+H41 | J41: 0 | K41: =ROUND(I41*J41/100,2) | L41: =I41+K41 | M41: 1.0365814 | N41: =ROUND(L41*M41,2) | O41: 5.4 | P41: =ROUND(N41*O41/100,2) | Q41: =N41+P41 | R41: =F41+N41-L41 | S41: =H41+K41+P41 | T41: 2025 | U41: mensal
A42: 01/2026 | B42: ='Evolução RMI'!H32 | C42: 0 | D42: =B42-C42 | E42: 1 | F42: =ROUND(D42*E42,2) | G42: 0 | H42: =ROUND(F42*G42/100,2) | I42: =F42+H42 | J42: 0 | K42: =ROUND(I42*J42/100,2) | L42: =I42+K42 | M42: 1.0324516 | N42: =ROUND(L42*M42,2) | O42: 4.8 | P42: =ROUND(N42*O42/100,2) | Q42: =N42+P42 | R42: =F42+N42-L42 | S42: =H42+K42+P42 | T42: 2026 | U42: mensal
...

Sheet Honorários
A1: Cálculo dos Honorários
A2: Nome do Segurado: | B2: JOSE EXEMPLO DA SILVA | D2: NIT: | E2: 111.22222.33-4
A3: CPF: | B3: 111.222.333-44 | D3: Data de Nascimento: | E3: 10/05/1962
A4: Sexo: | B4: Masculino | D4: Nº do Benefício:
A5: Espécie do Benefício: | B5: 42 - Aposentadoria por Tempo de Contribuição | D5: Nº do Processo: | E5: 0000000-00.2024.4.01.3800
A6: Início do Benefício (DIB): | B6: 01/03/2024 | D6: Data da Atualização: | E6: 15/09/2026
A7: Ajuizamento: | B7: 10/06/2024 | D7: Data da Prescrição: | E7: 01/03/2024
A9: Honorários de | B9: ='Parâmetros'!$B$21 | C9: % sobre a base de cálculo atualizada e sobre os juros.
A11: Data | B11: Base de Cálculo | C11: Base de Cálculo Atualizada | D11: Juros Sobre a Base de Cálculo | E11: Base Atualizada + Juros | F11: Valor Calculado
A12: 03/2024 | B12: ='Diferenças'!D16 | C12: ='Diferenças'!R16 | D12: ='Diferenças'!S16 | E12: =C12+D12 | F12: =ROUND(E12*'Parâmetros'!$B$21/100,2)
A13: 04/2024 | B13: ='Diferenças'!D17 | C13: ='Diferenças'!R17 | D13: ='Diferenças'!S17 | E13: =C13+D13 | F13: =ROUND(E13*'Parâmetros'!$B$21/100,2)
A14: 13º | B14: ='Diferenças'!D18 | C14: ='Diferenças'!R18 | D14: ='Diferenças'!S18 | E14: =C14+D14 | F14: =ROUND(E14*'Parâmetros'!$B$21/100,2)
A15: 05/2024 | B15: ='Diferenças'!D19 | C15: ='Diferenças'!R19 | D15: ='Diferenças'!S19 | E15: =C15+D15 | F15: =ROUND(E15*'Parâmetros'!$B$21/100,2)
A16: 13º | B16: ='Diferenças'!D20 | C16: ='Diferenças'!R20 | D16: ='Diferenças'!S20 | E16: =C16+D16 | F16: =ROUND(E16*'Parâmetros'!$B$21/100,2)
A17: 06/2024 | B17: ='Diferenças'!D21 | C17: ='Diferenças'!R21 | D17: ='Diferenças'!S21 | E17: =C17+D17 | F17: =ROUND(E17*'Parâmetros'!$B$21/100,2)
A18: 07/2024 | B18: ='Diferenças'!D22 | C18: ='Diferenças'!R22 | D18: ='Diferenças'!S22 | E18: =C18+D18 | F18: =ROUND(E18*'Parâmetros'!$B$21/100,2)
A19: 08/2024 | B19: ='Diferenças'!D23 | C19: ='Diferenças'!R23 | D19: ='Diferenças'!S23 | E19: =C19+D19 | F19: =ROUND(E19*'Parâmetros'!$B$21/100,2)
A20: 09/2024 | B20: ='Diferenças'!D24 | C20: ='Diferenças'!R24 | D20: ='Diferenças'!S24 | E20: =C20+D20 | F20: =ROUND(E20*'Parâmetros'!$B$21/100,2)
A21: 10/2024 | B21: ='Diferenças'!D25 | C21: ='Diferenças'!R25 | D21: ='Diferenças'!S25 | E21: =C21+D21 | F21: =ROUND(E21*'Parâmetros'!$B$21/100,2)
A22: 11/2024 | B22: ='Diferenças'!D26 | C22: ='Diferenças'!R26 | D22: ='Diferenças'!S26 | E22: =C22+D22 | F22: =ROUND(E22*'Parâmetros'!$B$21/100,2)
A23: 12/2024 | B23: ='Diferenças'!D27 | C23: ='Diferenças'!R27 | D23: ='Diferenças'!S27 | E23: =C23+D23 | F23: =ROUND(E23*'Parâmetros'!$B$21/100,2)
... A42: 13º | B42: ='Diferenças'!D46 | C42: ='Diferenças'!R46 | D42: ='Diferenças'!S46 | E42: =C42+D42 | F42: =ROUND(E42*'Parâmetros'!$B$21/100,2)
A43: Totais: | B43: =SUM(B12:B42) | C43: =SUM(C12:C42) | D43: =SUM(D12:D42) | E43: =SUM(E12:E42) | F43: =SUM(F12:F42)
A45: Sobre a Base Atualizada: | B45: =ROUND(C43*'Parâmetros'!$B$21/100,2)
A46: Sobre os Juros: | B46: =ROUND(D43*'Parâmetros'!$B$21/100,2)
A47: Valor Fixo: | B47: ='Parâmetros'!$B$23
A48: Total Geral de Honorários: | B48: =B45+B46+B47

Sheet IR (RRA)
A1: Informações para Imposto de Renda (Rendimentos Recebidos Acumuladamente)
A2: Nome do Segurado: | B2: JOSE EXEMPLO DA SILVA | D2: NIT: | E2: 111.22222.33-4
A3: CPF: | B3: 111.222.333-44 | D3: Data de Nascimento: | E3: 10/05/1962
A4: Sexo: | B4: Masculino | D4: Nº do Benefício:
A5: Espécie do Benefício: | B5: 42 - Aposentadoria por Tempo de Contribuição | D5: Nº do Processo: | E5: 0000000-00.2024.4.01.3800
A6: Início do Benefício (DIB): | B6: 01/03/2024 | D6: Data da Atualização: | E6: 15/09/2026
A7: Ajuizamento: | B7: 10/06/2024 | D7: Data da Prescrição: | E7: 01/03/2024
B9: Valor | C9: Meses
A10: Anos-base anteriores | B10: =SUMIFS('Diferenças'!$Q$16:$Q$51,'Diferenças'!$T$16:$T$51,"<2026") | C10: 24
A11: Ano-base atual (2026) | B11: =SUMIFS('Diferenças'!$Q$16:$Q$51,'Diferenças'!$T$16:$T$51,2026) | C11: 9
A12: Total | B12: =B10+B11 | C12: 33
A14: Meses: competências mensais + 1 mês por ano com 13º (art. 12-A da Lei 7.713/88).

Sheet Índices
A1: Índices mensais utilizados (%)
A3: Competência | B3: INPC | C3: SELIC | D3: TAXA LEGAL
A4: 03/2024 | B4: 0.4 | C4: 1
A5: 04/2024 | B5: 0.4 | C5: 1
A6: 05/2024 | B6: 0.4 | C6: 1
A7: 06/2024 | B7: 0.4 | C7: 1
A8: 07/2024 | B8: 0.4 | C8: 1
A9: 08/2024 | B9: 0.4 | C9: 1
A10: 09/2024 | B10: 0.4 | C10: 1
A11: 10/2024 | B11: 0.4 | C11: 1
A12: 11/2024 | B12: 0.4 | C12: 1
A13: 12/2024 | B13: 0.4 | C13: 1
A14: 01/2025 | C14: 1
A15: 02/2025 | C15: 1
A16: 03/2025 | C16: 1
A17: 04/2025 | C17: 1
A18: 05/2025 | C18: 1
A19: 06/2025 | C19: 1
A20: 07/2025 | C20: 1
A21: 08/2025 | C21: 1
A22: 09/2025 | B22: 0.4 | C22: 1 | D22: 0.6
A23: 10/2025 | B23: 0.4 | C23: 1 | D23: 0.6
A24: 11/2025 | B24: 0.4 | C24: 1 | D24: 0.6
A25: 12/2025 | B25: 0.4 | C25: 1 | D25: 0.6
A26: 01/2026 | B26: 0.4 | C26: 1 | D26: 0.6
A27: 02/2026 | B27: 0.4 | C27: 1 | D27: 0.6
A28: 03/2026 | B28: 0.4 | C28: 1 | D28: 0.6
A29: 04/2026 | B29: 0.4 | C29: 1 | D29: 0.6
A30: 05/2026 | B30: 0.4 | C30: 1 | D30: 0.6
A31: 06/2026 | B31: 0.4 | C31: 1 | D31: 0.6
A32: 07/2026 | B32: 0.4 | C32: 1 | D32: 0.6
A33: 08/2026 | B33: 0.4 | C33: 1 | D33: 0.6
A35: Fontes: IBGE/BCB-SGS (INPC 188, IGP-DI 190, IPCA-E 10764, SELIC 4390, meta SELIC 432) e Manual de Cálculos da Justiça Federal.

Sheet Avisos
A1: Pontos a conferir antes de usar o cálculo
A3: • RMI calculada pela regra 'Transição - pedágio 50%' (DIB 01/03/2024); confira com a carta de concessão.
A4: • reajuste de 2026 (3.9%) não foi conferido na fonte oficial
A5: • salario_minimo de 2026-01 (1621.0) não foi conferido na fonte oficial
A6: • teto de 2026-01 (8475.55) não foi conferido na fonte oficial
